Workbook

Sheet Operarios enero 2026
A1: Nombre | B1: Departamento | C1: Check | D1: Turno | E1: Linea
A2: Luis Moreno Arenas | B2: Producción | C2: =IF(COUNTBLANK((F2:BH2))=54,"Check",IF(COUNTBLANK(D2:BH2)=57,"Falta pedir","Ok")) -> Ok | D2: T2 | E2: BOX1
A3: Luis Bellon Hernandez | B3: Producción | C3: =IF(COUNTBLANK((F3:BH3))=54,"Check",IF(COUNTBLANK(D3:BH3)=57,"Falta pedir","Ok")) -> Ok | D3: T2 | E3: BOX1
A4: Marcos Monroy Prieto | B4: Producción | C4: =IF(COUNTBLANK((F4:BH4))=54,"Check",IF(COUNTBLANK(D4:BH4)=57,"Falta pedir","Ok")) -> Ok | D4: T2 | E4: BOX1
A5: SÁNCHEZ TORREJÓN, AARÓN | B5: Producción | C5: OK | D5: T2 | E5: BOX1
A6: PINTO, FÉLIX | B6: Producción | D6: T2 | E6: BOX1
A7: Miguel Torrejon Hernandez | B7: Producción - Mecanizado | C7: =IF(COUNTBLANK((F7:BH7))=54,"Check",IF(COUNTBLANK(D7:BH7)=57,"Falta pedir","Ok")) -> Ok | D7: S01 | E7: GOYO
A8: Alejandro Perez Ruiz | B8: Producción - Mecanizado | C8: =IF(COUNTBLANK((F8:BH8))=54,"Check",IF(COUNTBLANK(D8:BH8)=57,"Falta pedir","Ok")) -> Ok | D8: S01 | E8: GOYO
A9: Antonio Navarro Corral | B9: Producción - Mecanizado | C9: =IF(COUNTBLANK((F9:BH9))=54,"Check",IF(COUNTBLANK(D9:BH9)=57,"Falta pedir","Ok")) -> Ok | D9: S01 | E9: GOYO
A10: Daniel Donas Rodriguez | B10: Producción - Mecanizado | C10: =IF(COUNTBLANK((F10:BH10))=54,"Check",IF(COUNTBLANK(D10:BH10)=57,"Falta pedir","Ok")) -> Ok | D10: S01 | E10: GOYO
A11: Gonzalo Gonzalez De La Fuente | B11: Producción - Mecanizado | C11: =IF(COUNTBLANK((F11:BH11))=54,"Check",IF(COUNTBLANK(D11:BH11)=57,"Falta pedir","Ok")) -> Ok | D11: S01 | E11: GOYO
A12: Ivan Ramos Juarez | B12: Producción - Mecanizado | C12: =IF(COUNTBLANK((F12:BH12))=54,"Check",IF(COUNTBLANK(D12:BH12)=57,"Falta pedir","Ok")) -> Ok | D12: S01 | E12: GOYO
A13: Oliver Garcia Sanchez | B13: Producción - Mecanizado | C13: =IF(COUNTBLANK((F13:BH13))=54,"Check",IF(COUNTBLANK(D13:BH13)=57,"Falta pedir","Ok")) -> Ok | D13: S01 | E13: GOYO
A14: Pablo Villayandre Esteban | B14: Producción - Mecanizado | C14: =IF(COUNTBLANK((F14:BH14))=54,"Check",IF(COUNTBLANK(D14:BH14)=57,"Falta pedir","Ok")) -> Ok | D14: S01 | E14: GOYO
A15: Alberto Moreno Gonzalez | B15: Producción - Mecanizado | C15: =IF(COUNTBLANK((F15:BH15))=54,"Check",IF(COUNTBLANK(D15:BH15)=57,"Falta pedir","Ok")) -> Ok | D15: S01 | E15: GOYO
A16: Antonio Luque Pulido | B16: Producción - Mecanizado | C16: =IF(COUNTBLANK((F16:BH16))=54,"Check",IF(COUNTBLANK(D16:BH16)=57,"Falta pedir","Ok")) -> Ok | D16: S01 | E16: GOYO
A17: Bernardo Gonzalez Parra | B17: Producción - Mecanizado | C17: =IF(COUNTBLANK((F17:BH17))=54,"Check",IF(COUNTBLANK(D17:BH17)=57,"Falta pedir","Ok")) -> Ok | D17: S01 | E17: GOYO
A18: Carlos Vazquez Perez | B18: Producción - Mecanizado | C18: =IF(COUNTBLANK((F18:BH18))=54,"Check",IF(COUNTBLANK(D18:BH18)=57,"Falta pedir","Ok")) -> Ok | D18: S01 | E18: GOYO
... A32: Ronny Cuevo Torrez | B32: Producción - Mecanizado | C32: =IF(COUNTBLANK((F32:BH32))=54,"Check",IF(COUNTBLANK(D32:BH32)=57,"Falta pedir","Ok")) -> Ok | D32: S01 | E32: GOYO
A33: Jessica Cespedes Rosales | B33: Producción - Mecanizado - Excedencia | C33: =IF(COUNTBLANK((#REF!))=54,"Check",IF(COUNTBLANK(#REF!)=57,"Falta pedir","Ok")) -> #REF! | D33: S01 | E33: GOYO
A34: Alberto Rodriguez Rodriguez | B34: Producción | C34: OK | D34: T1 | E34: L1
A35: Angel Pascual Higueras | B35: Producción | C35: =IF(COUNTBLANK((G35:BJ35))=54,"Check",IF(COUNTBLANK(D35:BJ35)=57,"Falta pedir","Ok")) -> Falta pedir | D35: T1 | E35: L1
A36: David Fernandez Marina (COMITE) | B36: Producción | C36: =IF(COUNTBLANK((G36:BJ36))=54,"Check",IF(COUNTBLANK(D36:BJ36)=57,"Falta pedir","Ok")) -> Falta pedir | D36: T1 | E36: L1
A37: José Antonio Pichardo Espina | B37: Producción | C37: OK | D37: T1 | E37: L1
A38: Juan Mauricio Vicente Martin | B38: Producción | C38: OK | D38: T1 | E38: L1
A39: JERMAIN MANUEL OPORTE CALDERON, | B39: Producción | C39: ETT | D39: T1 | E39: L1
A40: RICARDO PRIETO GRANADOS, | B40: Producción | C40: ETT | D40: T1 | E40: L1
A41: Rafael Baños | B41: Producción | C41: OK | D41: T1 | E41: L1
A42: Samuel Dorado Ubeda | B42: Producción | C42: OK | D42: T1 | E42: L1
A43: Adrian Garcia Gutierrez | B43: Producción - Electricidad | C43: OK | D43: T1 | E43: L1
A44: Alexis Jesus Real Hernandez | B44: Producción - Electricidad | C44: OK | D44: T1 | E44: L1
A45: Fernando Jimenez Lopez | B45: Producción - Electricidad | C45: OK | D45: T1 | E45: L1
A46: Francisco Javier Ruiz Garcia | B46: Producción - Electricidad | C46: OK | D46: T1 | E46: L1
A47: Jose Luis Rodriguez Jarillo | B47: Producción - Electricidad | C47: OK | D47: T1 | E47: L1
A48: Rodrigo Da Silva Medeisos | B48: Producción - Electricidad | C48: OK | D48: T1 | E48: L1
A49: Cristian Gomez Marin | B49: Producción/baja | C49: BAJA | D49: T1 | E49: L1
A50: Miguel Angel Conejo Garcia | B50: Producción | C50: =IF(COUNTBLANK((F50:BH50))=54,"Check",IF(COUNTBLANK(D50:BH50)=57,"Falta pedir","Ok")) -> Ok | D50: T2 | E50: L1
A51: Victor Manuel Gallego Prieto | B51: Producción | C51: =IF(COUNTBLANK((F51:BH51))=54,"Check",IF(COUNTBLANK(D51:BH51)=57,"Falta pedir","Ok")) -> Ok | D51: T2 | E51: L1
A52: Angel Blazquez Fernandez | B52: Producción | C52: =IF(COUNTBLANK((F52:BH52))=54,"Check",IF(COUNTBLANK(D52:BH52)=57,"Falta pedir","Ok")) -> Ok | D52: T2 | E52: L1
A53: Antonio de Pablo | B53: Producción | C53: =IF(COUNTBLANK((F53:BH53))=54,"Check",IF(COUNTBLANK(D53:BH53)=57,"Falta pedir","Ok")) -> Ok | D53: T2 | E53: L1
...

Sheet Dashboard
A1: DASHBOARD — OPERARIOS POR LÍNEA | T1: Observaciones
A3: Tabla resumen de conteos por línea y categoría | T3: Línea 2
A4: Métrica | B4: Línea 1 | C4: Línea 2 | D4: Línea 3 | E4: Línea 4 | F4: Línea 5 | G4: Suma operarios | I4: Cuadros | K4: Necesidad en cuadros | L4: 2659 | M4: ITT PHASE 2
A5: Elec T1 | B5: ='Linea 1'!A2 -> 4 | C5: ='Linea 2'!A2 -> 3 | D5: ='Linea 3'!A2 -> 6 | E5: ='Linea 4'!A2 -> 2 | F5: ='Linea 5'!A2 -> 5 | G5: =SUM(B5:F5) -> 20 | H5: Elec T1 | I5: =Cuadros!K2 -> 8 | K5: Horas negativas | L5: =L4-I12 -> 409 | M5: NRT096 EAF PHASE 2
A6: Elec T2 | B6: ='Linea 1'!C2 -> 5 | C6: ='Linea 2'!C2 -> 4 | D6: ='Linea 3'!C2 -> 5 | E6: ='Linea 4'!C2 -> 3 | F6: ='Linea 5'!C2 -> 3 | G6: =SUM(B6:F6) -> 20 | H6: Elec T2 | I6: =Cuadros!K3 -> 7 | M6: KLON3 KAO
A7: Prod T1 | B7: ='Linea 1'!D2 -> 6 | C7: ='Linea 2'!D2 -> 9 | D7: ='Linea 3'!D2 -> 7 | E7: ='Linea 4'!D2 -> 4 | F7: ='Linea 5'!D2 -> 8 | G7: =SUM(B7:F7) -> 34 | H7: Elec T3 | I7: =Cuadros!K4 -> 0 | M7: Project Stack IT DC2
A8: Prod T2 | B8: ='Linea 1'!E2 -> 9 | C8: ='Linea 2'!E2 -> 9 | D8: ='Linea 3'!E2 -> 7 | E8: ='Linea 4'!E2 -> 5 | F8: 6 | G8: =SUM(B8:F8) -> 36 | M8: NRT096 EAF PHASE 2
B9: =SUM(B5:B8) -> 24 | C9: =SUM(C5:C8) -> 25 | D9: =SUM(D5:D8) -> 25 | E9: =SUM(E5:E8) -> 14 | F9: =SUM(F5:F8) -> 22 | I9: =SUM(I5:I8) -> 15
A10: Horas turno | B10: =B9*7.5 -> 180 | C10: =C9*7.5 -> 187.5 | D10: =D9*7.5 -> 187.5 | E10: =E9*7.5 -> 105 | F10: =F9*7.5 -> 165 | G10: =SUM(B10:F10) -> 825 | I10: =I9*7.5 -> 112.5 | J10: Dia
A11: Horas semana | B11: =5*B10 -> 900 | C11: =5*C10 -> 937.5 | D11: =5*D10 -> 937.5 | E11: =5*E10 -> 525 | F11: =5*F10 -> 825 | G11: =SUM(B11:F11) -> 4125 | I11: =5*I10 -> 562.5 | J11: Semana
A12: Horas mes | B12: =4*B11 -> 3600 | C12: =4*C11 -> 3750 | D12: =4*D11 -> 3750 | E12: =4*E11 -> 2100 | F12: =4*F11 -> 3300 | G12: =SUM(B12:F12) -> 16500 | I12: =4*I11 -> 2250 | J12: Mes
A13: Horas Elec. dia | B13: =B5+B6*7.55 -> 41.75 | C13: =C5+C6*7.55 -> 33.2 | D13: =D5+D6*7.55 -> 43.75 | E13: =E5+E6*7.55 -> 24.65 | F13: =F5+F6*7.55 -> 27.65 | G13: =G5+G6*7.55 -> 171
A14: Horas Mec. dia | B14: =B7+B8*7.55 -> 73.95 | C14: =C7+C8*7.55 -> 76.95 | D14: =D7+D8*7.55 -> 59.85 | E14: =E7+E8*7.55 -> 41.75 | F14: =F7+F8*7.55 -> 53.3 | G14: =G7+G8*7.55 -> 305.8
A15: Horas Elec. Sem. | B15: =B13*5 -> 208.75 | C15: =C13*5 -> 166 | D15: =D13*5 -> 218.75 | E15: =E13*5 -> 123.25 | F15: =F13*5 -> 138.25 | G15: =G13*5 -> 855
B35: Línea 1 | C35: Línea 2 | D35: Línea 3 | E35: Línea 4 | F35: Línea 5 | G35: BOX | H35: Absentismo | I35: Horas | J35: S5 | K35: Horas
A36: Mayo | B36: 38 | C36: 34 | D36: 22 | E36: 11 | F36: 34 | G36: 0 | H36: =SUM(B36:G36) -> 139 | I36: =H36*8 -> 1112 | K36: =J36*8 -> 0
A37: Junio | B37: 85 | C37: 50 | D37: 97 | E37: 39 | F37: 53 | G37: 2 | H37: =SUM(B37:G37) -> 326 | I37: =H37*8 -> 2608 | J37: 13 | K37: =J37*8 -> 104
A38: Julio | H38: 421 | I38: =H38*8 -> 3368 | K38: =J38*8 -> 0
A39: Agosto | H39: =SUM(B39:G39) -> 0 | I39: =H39*8 -> 0 | K39: =J39*8 -> 0
A40: Septiembre | H40: =SUM(B40:G40) -> 0 | I40: =H40*8 -> 0 | K40: =J40*8 -> 0
A41: Octubre | H41: =SUM(B41:G41) -> 0 | I41: =H41*8 -> 0 | K41: =J41*8 -> 0
A42: Noviembre | H42: =SUM(B42:G42) -> 0 | I42: =H42*8 -> 0 | K42: =J42*8 -> 0
A43: Diciembre | H43: =SUM(B43:G43) -> 0 | I43: =H43*8 -> 0 | K43: =J43*8 -> 0

Sheet Obj. Plantilla
A2: 1) OBJETIVO DE PLANTILLA POR LÍNEA
A4: Parte mecánica:
A5: - 9 operarios mecánicos fijos
A6: - 2 operarios mecánicos en formación
A7: - 1 jefe de equipo mecánico
A9: Parte eléctrica:
A10: - 4 operarios eléctricos fijos
A11: - 1 operario eléctrico en formación
A13: Estructura de mando:
A14: - El jefe de equipo (mecánico) y todos los operarios dependen del jefe de área.
A15: - Los jefes de equipos (mecanicos) computan como operarios.
A17: 2) CÓMPUTO DE LOS OPERARIOS EN FORMACIÓN
... A24: - Eléctrica: 4 + (1 × 0,30) = 4,3 FTE

Sheet Personal fabrica
E1: =COUNTA(E3:E171) -> 103 | F1: =COUNTA(F3:F171) -> 105
B2: Nombre | C2: Departamento | D2: Check | E2: Turno | F2: Linea
B3: Angel Pascual Higueras | C3: Producción | D3: =IF(COUNTBLANK((G3:BI3))=54,"Check",IF(COUNTBLANK(E3:BI3)=57,"Falta pedir","Ok")) -> Ok | E3: T1 | F3: L1
B4: José Antonio Pichardo Espina | C4: Producción | D4: =IF(COUNTBLANK((G4:BI4))=54,"Check",IF(COUNTBLANK(E4:BI4)=57,"Falta pedir","Ok")) -> Ok | E4: T1 | F4: L1
B5: Alberto Rodriguez Rodriguez | C5: Producción | D5: =IF(COUNTBLANK((G5:BI5))=54,"Check",IF(COUNTBLANK(E5:BI5)=57,"Falta pedir","Ok")) -> Ok | E5: T1 | F5: L1
B6: David Fernandez Marina | C6: Producción | D6: =IF(COUNTBLANK((G6:BI6))=54,"Check",IF(COUNTBLANK(E6:BI6)=57,"Falta pedir","Ok")) -> Ok | E6: T1 | F6: L1
B7: Juan Mauricio Vicente Martin | C7: Producción | D7: =IF(COUNTBLANK((G7:BI7))=54,"Check",IF(COUNTBLANK(E7:BI7)=57,"Falta pedir","Ok")) -> Ok | E7: T1 | F7: L1
B8: Rafael Baños | C8: Producción | D8: =IF(COUNTBLANK((G8:BI8))=54,"Check",IF(COUNTBLANK(E8:BI8)=57,"Falta pedir","Ok")) -> Ok | E8: T1 | F8: L1
B9: Samuel Dorado Ubeda | C9: Producción | D9: =IF(COUNTBLANK((G9:BI9))=54,"Check",IF(COUNTBLANK(E9:BI9)=57,"Falta pedir","Ok")) -> Ok | E9: T1 | F9: L1
B10: Maria Jesus Perales Cervera | C10: Producción | D10: =IF(COUNTBLANK((G10:BI10))=54,"Check",IF(COUNTBLANK(E10:BI10)=57,"Falta pedir","Ok")) -> Ok | E10: T1 | F10: L2
B11: Moises Rodriguez Del Barrio | C11: Producción | D11: =IF(COUNTBLANK((G11:BI11))=54,"Check",IF(COUNTBLANK(E11:BI11)=57,"Falta pedir","Ok")) -> Ok | E11: T1 | F11: L2
B12: Juan Felix Saez Vara | C12: Producción | D12: =IF(COUNTBLANK((G12:BI12))=54,"Check",IF(COUNTBLANK(E12:BI12)=57,"Falta pedir","Ok")) -> Ok | E12: T1 | F12: L2
B13: Carlos García | C13: Producción | D13: =IF(COUNTBLANK((G13:BI13))=54,"Check",IF(COUNTBLANK(E13:BI13)=57,"Falta pedir","Ok")) -> Ok | E13: T1 | F13: L2
B14: Mateo Jimenez Jurado | C14: Producción | D14: =IF(COUNTBLANK((G14:BI14))=54,"Check",IF(COUNTBLANK(E14:BI14)=57,"Falta pedir","Ok")) -> Ok | E14: T1 | F14: L3
... B28: Marcos Monroy Prieto | C28: Producción | D28: =IF(COUNTBLANK((G28:BI28))=54,"Check",IF(COUNTBLANK(E28:BI28)=57,"Falta pedir","Ok")) -> Ok | E28: T2 | F28: BOX1
B29: PINTO, FÉLIX | C29: Producción | E29: T2 | F29: BOX1
B30: SÁNCHEZ TORREJÓN, AARÓN | C30: Producción | E30: T2 | F30: BOX1
B31: Miguel Angel Conejo Garcia | C31: Producción | D31: =IF(COUNTBLANK((G31:BI31))=54,"Check",IF(COUNTBLANK(E31:BI31)=57,"Falta pedir","Ok")) -> Ok | E31: T2 | F31: L1
B32: Victor Manuel Gallego Prieto | C32: Producción | D32: =IF(COUNTBLANK((G32:BI32))=54,"Check",IF(COUNTBLANK(E32:BI32)=57,"Falta pedir","Ok")) -> Ok | E32: T2 | F32: L1
B33: Angel Blazquez Fernandez | C33: Producción | D33: =IF(COUNTBLANK((G33:BI33))=54,"Check",IF(COUNTBLANK(E33:BI33)=57,"Falta pedir","Ok")) -> Ok | E33: T2 | F33: L1
B34: Antonio de Pablo | C34: Producción | D34: =IF(COUNTBLANK((G34:BI34))=54,"Check",IF(COUNTBLANK(E34:BI34)=57,"Falta pedir","Ok")) -> Ok | E34: T2 | F34: L1
B35: Francisco Javier Abad García | C35: Producción | D35: =IF(COUNTBLANK((G35:BI35))=54,"Check",IF(COUNTBLANK(E35:BI35)=57,"Falta pedir","Ok")) -> Ok | E35: T2 | F35: L1
B36: Diego Antonio Panasiti | C36: Producción | D36: =IF(COUNTBLANK((G36:BI36))=54,"Check",IF(COUNTBLANK(E36:BI36)=57,"Falta pedir","Ok")) -> Ok | E36: T2 | F36: L1
B37: Francisco Luque Villoldo | C37: Producción - Electricidad | D37: =IF(COUNTBLANK((G37:BI37))=54,"Check",IF(COUNTBLANK(E37:BI37)=57,"Falta pedir","Ok")) -> Ok | E37: T2 | F37: L1
B38: Lourdes Rodriguez-Palancas Ramirez | C38: Producción - Electricidad | D38: =IF(COUNTBLANK((G38:BI38))=54,"Check",IF(COUNTBLANK(E38:BI38)=57,"Falta pedir","Ok")) -> Ok | E38: T2 | F38: L1
B39: Raul Olmo Bastante | C39: Producción - Electricidad | D39: =IF(COUNTBLANK((G39:BI39))=54,"Check",IF(COUNTBLANK(E39:BI39)=57,"Falta pedir","Ok")) -> Ok | E39: T2 | F39: L1
B40: Alberto Fernandez Marina | C40: Producción | D40: =IF(COUNTBLANK((G40:BI40))=54,"Check",IF(COUNTBLANK(E40:BI40)=57,"Falta pedir","Ok")) -> Ok | E40: T2 | F40: L2
B41: Angel Luis Guerrero Pantoja | C41: Producción | D41: =IF(COUNTBLANK((G41:BI41))=54,"Check",IF(COUNTBLANK(E41:BI41)=57,"Falta pedir","Ok")) -> Ok | E41: T2 | F41: L2
B42: Ismael Lozano Torrejón | C42: Producción | D42: =IF(COUNTBLANK((G42:BI42))=54,"Check",IF(COUNTBLANK(E42:BI42)=57,"Falta pedir","Ok")) -> Ok | E42: T2 | F42: L2
... B56: Angel Benaigues | C56: Producción - Electricidad | D56: =IF(COUNTBLANK((G56:BI56))=54,"Check",IF(COUNTBLANK(E56:BI56)=57,"Falta pedir","Ok")) -> Ok | E56: T2 | F56: L3
B57: Aitor Benito Figueroa | C57: Producción - Baterías | D57: =IF(COUNTBLANK((G57:BI57))=54,"Check",IF(COUNTBLANK(E57:BI57)=57,"Falta pedir","Ok")) -> Falta pedir
B58: Alvaro Garcia Ruz | C58: Producción - Baterías | D58: =IF(COUNTBLANK((G58:BI58))=54,"Check",IF(COUNTBLANK(E58:BI58)=57,"Falta pedir","Ok")) -> Falta pedir
B59: Andreina G. Paladines Gonzalez | C59: Producción - Baterías | D59: =IF(COUNTBLANK((G59:BI59))=54,"Check",IF(COUNTBLANK(E59:BI59)=57,"Falta pedir","Ok")) -> Falta pedir
B60: Antonio Bayon Gomez | C60: Producción - Baterías | D60: =IF(COUNTBLANK((G60:BI60))=54,"Check",IF(COUNTBLANK(E60:BI60)=57,"Falta pedir","Ok")) -> Falta pedir
B61: Antonio Rodriguez Jimenez | C61: Producción - Baterías | D61: =IF(COUNTBLANK((G61:BI61))=54,"Check",IF(COUNTBLANK(E61:BI61)=57,"Falta pedir","Ok")) -> Falta pedir
B62: Antonio Saelices Zaragoza | C62: Producción - Baterías | D62: =IF(COUNTBLANK((G62:BI62))=54,"Check",IF(COUNTBLANK(E62:BI62)=57,"Falta pedir","Ok")) -> Falta pedir
B63: David Medina Montes | C63: Producción - Baterías | D63: =IF(COUNTBLANK((G63:BI63))=54,"Check",IF(COUNTBLANK(E63:BI63)=57,"Falta pedir","Ok")) -> Falta pedir
B64: Diakaridia Sangare Diakite | C64: Producción - Baterías | D64: =IF(COUNTBLANK((G64:BI64))=54,"Check",IF(COUNTBLANK(E64:BI64)=57,"Falta pedir","Ok")) -> Falta pedir
B65: Diona Cosmina Florea | C65: Producción - Baterías | D65: =IF(COUNTBLANK((G65:BI65))=54,"Check",IF(COUNTBLANK(E65:BI65)=57,"Falta pedir","Ok")) -> Falta pedir
B66: Eugenio Alfonso Rodrigo Santiago | C66: Producción - Baterías | D66: =IF(COUNTBLANK((G66:BI66))=54,"Check",IF(COUNTBLANK(E66:BI66)=57,"Falta pedir","Ok")) -> Falta pedir
...

Sheet ETT
A1: HUGO | B1: Empleado | C1: Empresa | D1: Cost | E1: Sección | F1: Fecha Inicio | G1: Columna1 | H1: Columna2 | I1: Columna3 | J1: TURNO
A2: 35 | B2: ALISTE DIAZ, ENRIQUE | C2: Aura | D2: Direct | E2: Mechanical | F2: 46084 | G2: L1 | H2: Mecanico | I2: ANTONIO | J2: T2 | K2: TURNO 1
A3: 33 | B3: CHAVES LEMETRE, ISMAEL JOSE | C3: EuroFirms | D3: Direct | E3: Electrical | F3: 46048 | G3: L1 | H3: Electrico | I3: ANTONIO | J3: T2 | K3: SONIA S03
A4: 34 | B4: VARE LA RIVA, HERNAN ALEJANDRO | C4: Aura | D4: Direct | E4: Mechanical | F4: 46081 | G4: L1 | H4: Mecanico | I4: ANTONIO | J4: T2 | K4: GOYO S01
A5: 36 | B5: VAZQUEZ TORREJON, ARANZAZU | C5: Aura | D5: Direct | E5: Mechanical | F5: 46084 | G5: L1 | H5: Mecanico | I5: ANTONIO | J5: T2 | K5: TURNO 2
A6: 79 | B6: BETANCUR CASTRO, JHON STIVEN | C6: Aura | D6: Direct | E6: Mechanical | F6: 46062 | G6: L5 | H6: Mecanico | I6: ANTONIO A. | J6: T1
A7: 86 | B7: CAMPOS MARTÍN, NAYARA | C7: EuroFirms | D7: Direct | E7: Mechanical | F7: 46188 | G7: L5 | H7: Mecanico | I7: ANTONIO A. | J7: T1
A8: 80 | B8: CASTELLANOS RODRIGUEZ, NELSON ANDRES | C8: Aura | D8: Direct | E8: Mechanical | F8: 46062 | G8: L5 | H8: Mecanico | I8: ANTONIO A. | J8: T1
A9: 81 | B9: DORADO DEL CERRO, AISHA | C9: Aura | D9: Direct | E9: Mechanical | F9: 46084 | G9: L5 | H9: Mecanico | I9: ANTONIO A. | J9: T1
A10: 78 | B10: GONZALEZ ROBLES, ISMAEL | C10: Aura | D10: Direct | E10: Mechanical | F10: 46029 | G10: L5 | H10: Mecanico | I10: ANTONIO A. | J10: T1
A11: 19 | B11: SÁNCHEZ TORREJÓN, AARÓN | C11: EuroFirms | D11: Direct | E11: Mechanical | F11: 46125 | G11: BOX1 | H11: Mecanico | I11: BOX1 | J11: T2
A12: 51 | B12: Alicia Aparicio | C12: Aura | D12: Direct | E12: Mechanical | F12: 46167 | G12: L2 | H12: Mecanico | I12: CARLOS | J12: T1
A13: 50 | B13: DINU POP, DENIS RAZVAN | C13: EuroFirms | D13: Direct | E13: Mechanical | F13: 46048 | G13: L2 | H13: Mecanico | I13: CARLOS | J13: T1
A14: 41 | B14: HERNANDEZ LOPEZ-BALTASAR, DAVID | C14: Aura | D14: Direct | E14: Electrical | F14: 46062 | G14: L2 | H14: Mecanico | I14: Carlos
A15: 42 | B15: JUAREZ ANDY | C15: Aura | D15: Direct | E15: Mechanical | F15: 46125 | G15: L2 | H15: Mecanico | I15: Carlos
A16: 91 | B16: NGANDU KABONGO, SANDERS | C16: EuroFirms | D16: Direct | E16: Mechanical | F16: 46188 | G16: L2 | H16: Mecanico | I16: CARLOS | J16: T1
A17: 90 | B17: PÁLAMO BOJE, ÁLVARO FELIPE | C17: Aura | D17: Direct | E17: Mechanical | F17: 46188 | G17: L2 | H17: Mecanico | I17: CARLOS | J17: T1
A18: 49 | B18: VARGAS GUTIERREZ, HUGO | C18: Aura | D18: Direct | E18: Mechanical | F18: 46029 | G18: L2 | H18: Mecanico | I18: CARLOS | J18: T1
A19: 48 | B19: IZQUIERDO, DAVID | C19: EuroFirms | D19: Direct | G19: L2 | H19: Mecanico | I19: CARLOS | J19: T1
A20: 49 | B20: JUAREZ ANDY | C20: Aura | D20: Direct | G20: L2 | H20: Mecanico | I20: CARLOS | J20: T1
A21: 28 | B21: MORENO RISCO, JUAN LUIS | C21: Aura | D21: Direct | E21: E-Panel | F21: 45985 | G21: Cuadros | H21: Electrico | I21: CARMELO | J21: T2
A22: 29 | B22: SOLERA BRICIO, IARA | C22: STULZ Tecnivel | D22: Direct | E22: Electrical | F22: 46146 | G22: Cuadros | H22: Electrico | I22: CARMELO | J22: T2
A23: 84 | B23: FRANCO DELGADO, OMAR FERNANDO | C23: STULZ Tecnivel | D23: Direct | E23: Electrical | F23: 46153 | G23: L5 | H23: Electrico | I23: CARMELO | J23: T2
A24: 85 | B24: IVAN FERNANDEZ ESPINOSA | C24: EuroFirms | D24: Direct | E24: Electrical | F24: 46153 | G24: L5 | H24: Electrico | I24: CARMELO | J24: T2
A25: 39 | B25: GONZALEZ, FRANK | C25: EuroFirms | D25: Direct | E25: Electrical | F25: 46167 | G25: L1 | I25: CARMELO | J25: T2 | K25: CESE
A26: 31 | B26: ESTRADA ACEVEDO, JHON FERNANDO | C26: EuroFirms | D26: Direct | E26: Electrical | F26: 46174 | G26: Cuadros | H26: Electrico | I26: CARMELO | J26: T2
A27: 32 | B27: KASMI, FAYSAL NO SEINCORPORA AUN | C27: EuroFirms | D27: Direct | E27: Electrical | F27: 46203 | G27: Cuadros | H27: Electrico | I27: CARMELO | J27: T2
A28: 72 | B28: AGUADO CABALLERO, LUCIA | C28: EuroFirms | D28: Direct | E28: Electrical | F28: 46167 | G28: L4 | H28: Mecanico | I28: DAVID | J28: T1
A29: 73 | B29: APARICIO ORTEGA VILLAIZAN, ALEJANDRO | C29: EuroFirms | D29: Direct | E29: Mechanical | F29: 46174 | G29: L4 | H29: Mecanico | I29: DAVID | J29: T1
A30: 66 | B30: GONZALEZ DEL VALLE, ROBERTO | C30: EuroFirms | D30: Direct | E30: Mechanical | F30: 46076 | G30: L4 | H30: Mecanico | I30: DAVID
A31: 65 | B31: GONZALEZ RIOS, FRANK STIBEN | C31: Aura | D31: Direct | E31: Mechanical | F31: 46160 | G31: L4 | H31: Mecanico | I31: DAVID
A32: 64 | B32: IZQUIERDO, DAVID | C32: EuroFirms | D32: Direct | E32: Mechanical | F32: 46153 | G32: L4 | H32: Mecanico | I32: DAVID
A33: 92 | B33: NICULA, STEFAN | C33: Aura | D33: Direct | E33: Mechanical | F33: 46188 | G33: L4 | H33: Mecanico | I33: DAVID | J33: T1
A34: 69 | B34: TAPIAS FRANCO, DANIELA | C34: STULZ Tecnivel | D34: Direct | E34: Electrical | F34: 46146 | G34: L4 | H34: Electrico | I34: DAVID | J34: T1
A35: 68 | B35: QUINTANA GONZALEZ, NAIARA | C35: Aura | D35: Direct | E35: Mechanical | F35: 46084 | G35: L4 | H35: Mecanico | I35: DAVID | J35: T1
A36: 71 | B36: SILVIU CONSTANTIN, IOSIF | C36: Aura | D36: Direct | E36: Mechanical | F36: 46160 | G36: L4 | H36: Mecanico | I36: DAVID | J36: T1
A37: 30 | B37: TRIVIÑO GUERRERO, LUCIA | C37: STULZ Tecnivel | D37: Direct | E37: Electrical | F37: 46146 | G37: Cuadros | H37: Electrico | I37: FEDERICO | J37: T1
A38: 93 | B38: VASQUEZ ORTEGA, JUAN JOSE | C38: EuroFirms | D38: Direct | E38: Electrical | F38: 46195 | G38: L1 | H38: Electrico | I38: FEDERICO | J38: T1
A39: 57 | B39: VILLANUEVA OLMEDO, Mª DOLORES | C39: STULZ Tecnivel | D39: Direct | E39: Electrical | F39: 46146 | G39: L3 | H39: Electrico | I39: FRAN | J39: T2
A40: 22 | B40: GOETE, TARIEL | C40: Aura | D40: Direct | E40: SheetMetal | F40: 46055 | G40: CNC | H40: Mecanizado | I40: GOYO
...

Sheet Absentismo
A1: Linea | B1: 46144 | C1: 46145 | D1: 46146 | E1: 46147 | F1: 46148 | G1: 46149 | H1: 46150 | I1: 46151 | J1: 46152 | K1: 46153 | L1: 46154 | M1: 46155 | N1: 46156 | O1: 46157 | P1: 46158 | Q1: 46159 | R1: 46160 | S1: 46161 | T1: 46162 | U1: 46163 | V1: 46164 | W1: 46165 | X1: 46166 | Y1: 46167 | Z1: 46168 | AA1: 46169 | AB1: 46170 | AC1: 46171 | AD1: 46172 | AE1: 46173 | AF1: 46174 | AG1: 46175 | AH1: 46176 | AI1: 46177 | AJ1: 46178 | AK1: 46179 | AL1: 46180 | AM1: 46181 | AN1: 46182 | AO1: 46183 | AP1: 46184 | AQ1: 46185 | AR1: 46186 | AS1: 46187 | AT1: 46188 | AU1: 46189 | AV1: 46190 | AW1: 46191 | AX1: 46192 | AY1: 46193 | AZ1: 46194 | BA1: 46195 | BB1: 46196 | BC1: 46197 | BD1: 46198 | BE1: 46199 | BF1: 46200 | BG1: 46201 | BH1: 46202 | BI1: 46203 | BJ1: 46204 | BK1: 46205 | BL1: 46206
A2: L4 | E2: NUNES MARIA, PAULO JORGE
A3: L2 | E3: VICTOR MANUEL MORENO CRUZ
A4: L5 | F4: PEDRO P. SANCHEZ CENAMOR
A5: L2 | F5: VICTOR MANUEL MORENO CRUZ
A6: L1 | F6: FERNANDO JIMENEZ LOPEZ
A7: L1 | F7: JOSE LUIS RODRIGUEZ JARILLO
A8: L2 | F8: DANIEL BARROSO DE ROA
A9: L3 | F9: JAVIER UREÑA PORTERO
A10: L2 | G10: VICTOR MANUEL MORENO CRUZ | H10: VICTOR MANUEL MORENO CRUZ
A11: L5 | H11: GARCIA GUERRA, CARLOS
A12: L1 | H12: RODRIGUEZ RODRIGUEZ, ALBERTO
A13: L1 | H13: OPORTE CALDERON, JERMAIN MANUEL
A14: L1 | H14: JIMENEZ LOPEZ , FERNANDO
A15: L3 | H15: JUANES CARMONA, CHRISTIAN
A16: L3 | H16: BARROSO DE ROA, DANIEL
A17: L3
A18: L3 | K18: JAVIER BLANCO | L18: JAVIER BLANCO | M18: JAVIER BLANCO | N18: JAVIER BLANCO | O18: JAVIER BLANCO
A19: L5 | K19: CASTELLANOS RODRIGUEZ, NELSON ANDRES
A20: L4 | K20: CHAMARRO GARCIA, WESTLEY
A21: L5 | K21: GARCIA GUERRA, CARLOS
A22: L2 | L22: CORDON MORENO SAMIUEL
A23: L5 | L23: GARCIA GUERRA, CARLOS
A24: L5 | M24: GARCIA GUERRA, CARLOS | N24: GARCIA GUERRA, CARLOS | O24: GARCIA GUERRA, CARLOS | R24: GARCIA GUERRA, CARLOS | S24: GARCIA GUERRA, CARLOS | T24: GARCIA GUERRA, CARLOS | U24: GARCIA GUERRA, CARLOS | V24: GARCIA GUERRA, CARLOS | Y24: GARCIA GUERRA, CARLOS | Z24: GARCIA GUERRA, CARLOS | AA24: GARCIA GUERRA, CARLOS | AB24: GARCIA GUERRA, CARLOS
A25: L1 | M25: PRIETO GRANADOS RICARDO
A26: L4 | M26: ALEJANDRO MARTIN GARCIA
A27: L1 | N27: PRIETO GRANADOS RICARDO
A28: L1 | N28: REAL HERNANDEZ, ALEXIS JESUS
A29: L1 | N29: JIMENEZ LOPEZ , FERNANDO
A30: L2 | N30: MORENO CRUZ, VICTOR MANUEL
A31: L3 | N31: BARROSO DE ROA, DANIEL
A32: L1 | N32: ANGEL BLAZQUEZ FERNANDEZ
A33: L1 | O33: PICHARDO ESPINA , JOSE ANTONIO
A34: L1 | O34: DA SILVA MEDEISOS, RODRIGO
A35: L1 | O35: PRIETO GRANADOS RICARDO
A36: L2 | O36: NIETO TRUJILLO, VALENTIN
A37: L4 | O37: HERRANDO GARCIA, ALBERTO
A38: L5 | O38: GONZALEZ ROBLES ISMAEL | R38: GONZALEZ ROBLES, ISMAEL | S38: GONZALEZ ROBLES, ISMAEL | T38: GONZALEZ ROBLES, ISMAEL | U38: GONZALEZ ROBLES, ISMAEL | Z38: GONZALEZ ROBLES, ISMAEL | AA38: GONZALEZ ROBLES, ISMAEL | AB38: GONZALEZ ROBLES, ISMAEL | AC38: GONZALEZ ROBLES, ISMAEL
A39: L1 | O39: BALQUEZ FERNANDEZ, ANGEL
A40: L1 | O40: ABAD GARCIA, FRANCISCO JAVIER
...

Sheet Linea 1
A1: Producción - Electricidad - T1 | B1: ID Operario | C1: Producción - Electricidad T2 | D1: Producción - T1 | E1: Producción - T2 | F1: Total operarios | J1: Categoría | K1: Cantidad
A2: =SUMPRODUCT((D5:D9994="Producción - Electricidad")*(E5:E9994="OK")*(F5:F9994="T1")*(1+ISNUMBER(H5:H9994)*((0.2+0.3*(IFERROR((TODAY()-H5:H9994)/30.44,0)>3)+0.25*(IFERROR((TODAY()-H5:H9994)/30.44,0)>6)+0.25*(IFERROR((TODAY()-H5:H9994)/30.44,0)>9))-1))) -> 4 | C2: =SUMPRODUCT((D5:D9994="Producción - Electricidad")*(E5:E9994="OK")*(F5:F9994="T2")*(1+ISNUMBER(H5:H9994)*((0.2+0.3*(IFERROR((TODAY()-H5:H9994)/30.44,0)>3)+0.25*(IFERROR((TODAY()-H5:H9994)/30.44,0)>6)+0.25*(IFERROR((TODAY()-H5:H9994)/30.44,0)>9))-1))) -> 5 | D2: =SUMPRODUCT((D5:D9994="Producción")*(E5:E9994="OK")*(F5:F9994="T1")*(1+ISNUMBER(H5:H9994)*((0.2+0.3*(IFERROR((TODAY()-H5:H9994)/30.44,0)>3)+0.25*(IFERROR((TODAY()-H5:H9994)/30.44,0)>6)+0.25*(IFERROR((TODAY()-H5:H9994)/30.44,0)>9))-1))) -> 6 | E2: =SUMPRODUCT((D5:D9994="Producción")*(E5:E9994="OK")*(F5:F9994="T2")*(1+ISNUMBER(H5:H9994)*((0.2+0.3*(IFERROR((TODAY()-H5:H9994)/30.44,0)>3)+0.25*(IFERROR((TODAY()-H5:H9994)/30.44,0)>6)+0.25*(IFERROR((TODAY()-H5:H9994)/30.44,0)>9))-1))) -> 9 | F2: =SUM(A2:E2) -> 24 | J2: Elec-T1 | K2: =A2 -> 4
J3: Elec-T2 | K3: =C2 -> 5
A4: Cantidad | B4: ID Operario | C4: Nombre | D4: Departamento | E4: Estado | F4: Turno | G4: Linea | H4: ETT | I4: Fecha | J4: Prod-T1 | K4: =D2 -> 6
A5: 1 | B5: DFM | C5: FERNANDEZ MARINA, DAVID | D5: Producción/baja | E5: Baja | F5: T1 | G5: L1 | H5: Sindicato | I5: Sindicato | J5: Prod-T2 | K5: =E2 -> 9
A6: 2 | B6: CGM | C6: GOMEZ MARIN, CRISTIAN | D6: Producción/baja | E6: Baja | F6: T1 | G6: L1
A7: 3 | B7: RDSM | C7: DA SILVA MEDEIROS, RODRIGO (Paternidad) | D7: Producción - Electricidad baja | E7: Baja | F7: T1 | G7: L1
A8: 4 | B8: JLRJ | C8: RODRIGUEZ JARILLO, JOSE LUIS | D8: Producción - Electricidad baja | E8: Baja | F8: T1 | G8: L1
A9: 5 | C9: BAÑOS RAFAEL | D9: Producción | E9: Jefe | F9: T1 | G9: L1
A10: 6 | B10: APHI | C10: PASCUAL HIGUERAS, ANGEL | D10: Producción | E10: OK | F10: T1 | G10: L1
A11: 8 | B11: SDU | C11: DORADO UBEDA , SAMUEL | D11: Producción | E11: OK | F11: T1 | G11: L1
A12: 9 | B12: JAPE | C12: PICHARDO ESPINA , JOSE ANTONIO | D12: Producción | E12: OK | F12: T1 | G12: L1
A13: 10 | B13: RPG | C13: PRIETO GRANADOS, RICARDO | D13: Producción | E13: OK | F13: T1 | G13: L1 | H13: ETT | I13: 46076
A14: 11 | B14: ARR | C14: RODRIGUEZ RODRIGUEZ, ALBERTO | D14: Producción | E14: OK | F14: T1 | G14: L1
A15: 12 | B15: JMVM | C15: VICENTE MARTIN, JUAN MAURICIO | D15: Producción | E15: OK | F15: T1 | G15: L1
A16: 13 | B16: AGG | C16: GARCIA GUTIERREZ, ADRIAN | D16: Producción - Electricidad | E16: OK | F16: T1 | G16: L1
A17: 14 | B17: FJL | C17: JIMENEZ LOPEZ , FERNANDO | D17: Producción - Electricidad | E17: OK | F17: T1 | G17: L1 | H17: Sindicato | I17: Sindicato
A18: 15 | B18: AJRH | C18: REAL HERNANDEZ, ALEXIS JESUS | D18: Producción - Electricidad | E18: OK | F18: T1 | G18: L1
A19: 16 | B19: JJVO | C19: VASQUEZ ORTEGA, JUAN JOSE | D19: Producción - Electricidad | E19: OK | F19: T1 | G19: L1 | H19: ETT | I19: 46195
A20: 17 | B20: ADPG | C20: DE PABLO, ANTONIO | D20: Producción | E20: Jefe | F20: T2 | G20: L1
A21: 18 | B21: MACG | C21: CONEJO GARCIA, MIGUEL ANGEL | D21: Producción | E21: OK | F21: T2 | G21: L1
A22: 19 | B22: VMGP | C22: GALLEGO PRIETO, VICTOR MANUEL | D22: Producción | E22: OK | F22: T2 | G22: L1
A23: 20 | B23: ABF | C23: BALQUEZ FERNANDEZ, ANGEL Calidad | D23: Producción | E23: OK | F23: T2 | G23: L1
A24: 21 | B24: FJAG | C24: ABAD GARCIA, FRANCISCO JAVIER | D24: Producción | E24: OK | F24: T2 | G24: L1
A25: 22 | B25: DAP | C25: PANASITI, DIEGO ANTONIO | D25: Producción | E25: OK | F25: T2 | G25: L1
A26: 23 | B26: HAVR | C26: VARE LA RIVA, HERNAN ALEJANDRO | D26: Producción | E26: OK | F26: T2 | G26: L1 | H26: ETT | I26: 46081
A27: 24 | B27: EAD | C27: ALISTE DIAZ, ENRIQUE | D27: Producción | E27: OK | F27: T2 | G27: L1 | H27: ETT | I27: 46084
A28: 25 | B28: AVT | C28: VAZQUEZ TORREJON, ARANZAZU | D28: Producción | E28: OK | F28: T2 | G28: L1 | H28: ETT | I28: 46084
A29: 26 | B29: AGR | C29: GARCIA RUZ, ALVARO BATERIAS | D29: Producción | E29: OK | F29: T2 | G29: L1
A30: 27 | B30: FLV | C30: LUQUE VILLOLDO, FRANCISCO L5 | D30: Producción - Electricidad | E30: OK | F30: T2 | G30: L1
A31: 28 | B31: LRPR | C31: RODRIGUZ PALANCAS RAMIREZ, LOURDES | D31: Producción - Electricidad | E31: OK | F31: T2 | G31: L1
A32: 29 | B32: JROB | C32: OLMO BASTANTE, JOSE RAUL | D32: Producción - Electricidad | E32: OK | F32: T2 | G32: L1
A33: 30 | B33: ICL | C33: CHAVES LEMETRE, ISMAEL JOSE | D33: Producción - Electricidad | E33: OK | F33: T2 | G33: L1 | H33: ETT | I33: 46048
A34: 31 | B34: ARDC | C34: RODRIGUES DE CARVALHO, ANDRE L3 | D34: Producción - Electricidad | E34: OK | F34: T2 | G34: L1 | H34: ETT | I34: 46167

Sheet Linea 2
A1: Producción - Electricidad - T1 | B1: ID Operario | C1: Producción - Electricidad T2 | D1: Producción - T1 | E1: Producción - T2 | F1: Total operarios | J1: Categoría | K1: Cantidad
A2: =SUMPRODUCT((D5:D9992="Producción - Electricidad")*(E5:E9992="OK")*(F5:F9992="T1")*(1+ISNUMBER(H5:H9992)*((0.2+0.3*(IFERROR((TODAY()-H5:H9992)/30.44,0)>3)+0.25*(IFERROR((TODAY()-H5:H9992)/30.44,0)>6)+0.25*(IFERROR((TODAY()-H5:H9992)/30.44,0)>9))-1))) -> 3 | C2: =SUMPRODUCT((D5:D9992="Producción - Electricidad")*(E5:E9992="OK")*(F5:F9992="T2")*(1+ISNUMBER(H5:H9992)*((0.2+0.3*(IFERROR((TODAY()-H5:H9992)/30.44,0)>3)+0.25*(IFERROR((TODAY()-H5:H9992)/30.44,0)>6)+0.25*(IFERROR((TODAY()-H5:H9992)/30.44,0)>9))-1))) -> 4 | D2: =SUMPRODUCT((D5:D9992="Producción")*(E5:E9992="OK")*(F5:F9992="T1")*(1+ISNUMBER(H5:H9992)*((0.2+0.3*(IFERROR((TODAY()-H5:H9992)/30.44,0)>3)+0.25*(IFERROR((TODAY()-H5:H9992)/30.44,0)>6)+0.25*(IFERROR((TODAY()-H5:H9992)/30.44,0)>9))-1))) -> 9 | E2: =SUMPRODUCT((D5:D9992="Producción")*(E5:E9992="OK")*(F5:F9992="T2")*(1+ISNUMBER(H5:H9992)*((0.2+0.3*(IFERROR((TODAY()-H5:H9992)/30.44,0)>3)+0.25*(IFERROR((TODAY()-H5:H9992)/30.44,0)>6)+0.25*(IFERROR((TODAY()-H5:H9992)/30.44,0)>9))-1))) -> 9 | F2: =SUM(A2:E2) -> 25 | J2: Elec-T1 | K2: =A2 -> 3
J3: Elec-T2 | K3: =C2 -> 4
A4: Cantidad | B4: ID Operario | C4: Nombre | D4: Departamento | E4: Estado | F4: Turno | G4: Linea | H4: ETT | I4: Fecha | J4: Prod-T1 | K4: =D2 -> 9
A5: 1 | C5: Carlos García | D5: Producción | E5: Jefe | F5: T1 | G5: L2 | J5: Prod-T2 | K5: =E2 -> 9
A6: 2 | B6: MJPC | C6: PERALES CERVERA, Mª JESUS | D6: Producción | E6: OK | F6: T1 | G6: L2
A7: 3 | B7: JFSV | C7: SAEZ VARA, JUAN FELIX | D7: Producción | E7: OK | F7: T1 | G7: L2
A8: 4 | B8: HVG | C8: VARGAS GUTIERREZ, HUGO | D8: Producción | E8: OK | F8: T1 | G8: L2 | H8: ETT | I8: 46029
A9: 5 | B9: DRDP | C9: DINU POP, DENIS RAZVAN | D9: Producción | E9: OK | F9: T1 | G9: L2 | H9: ETT | I9: 46048
A10: 6 | B10: CGV | C10: GÓMEZ VICOU, CHRISTIAN | D10: Producción | E10: OK | F10: T1 | G10: L2 | H10: ETT | I10: 46062
A11: 7 | B11: AALO | C11: APARICIO LOSADA, ALICIA | D11: Producción | E11: OK | F11: T1 | G11: L2 | H11: ETT | I11: 46167
A12: 8 | B12: JSM | C12: SANCHEZ MADRIGAL, JAVIER BATERIAS | D12: Producción | E12: OK | F12: T1 | G12: L2
A13: 9 | B13: SNK | C13: NGANDU KABONGO, SANDERS | D13: Producción | E13: OK | F13: T1 | G13: L2 | H13: ETT | I13: 46188
A14: 10 | B14: AFPB | C14: PÁLAMO BOJE, ÁLVARO FELIPE | D14: Producción | E14: OK | F14: T1 | G14: L2 | H14: ETT | I14: 46188
A15: 11 | B15: DMQ | C15: MARTIN QUINTERO, DAVID | D15: Producción - Electricidad | E15: OK | F15: T1 | G15: L2
A16: 12 | B16: LEGE | C16: GUANILLO ESQUECHE, LUIS ENRIQUE | D16: Producción - Electricidad - L3 | E16: OK | F16: T1 | G16: L2
A17: 13 | B17: BAJM | C17: MARQUES JABATO, BLANCA AMALIA | D17: Producción - Electricidad | E17: OK | F17: T1 | G17: L2
A18: 14 | B18: VNT | C18: NIETO TRUJILLO, VALENTIN | D18: Producción - Electricidad - L3 | E18: OK | F18: T1 | G18: L2
A19: 15 | B19: VMMC | C19: MORENO CRUZ, VICTOR MANUEL | D19: Producción - Electricidad | E19: OK | F19: T1 | G19: L2 | H19: Sindicato | I19: Sindicato
A20: 16 | B20: RMPH | C20: PALACIOS HARO, ROSA MARIA | D20: Producción/Baja | E20: Baja | F20: T1 | G20: L2
A21: 17 | C21: GARCIA, SERGIO | D21: Producción | E21: Jefe | F21: T2 | G21: L2
A22: 18 | B22: AFM | C22: FERNANDEZ MARINA, ALBERTO (SOLO TARDE) | D22: Producción/Baja | E22: OK | F22: T2 | G22: L2
A23: 19 | B23: ALGP | C23: GERRERO PANTOJA, ANGEL LUIS | D23: Producción | E23: OK | F23: T2 | G23: L2
A24: 20 | B24: ILT | C24: LOZANO TORREJON, ISMAEL | D24: Producción | E24: OK | F24: T2 | G24: L2
A25: 21 | B25: SCM | C25: CORDON MORENO, SAMUEL | D25: Producción | E25: OK | F25: T2 | G25: L2
A26: 22 | B26: PFL | C26: FERNANDEZ LAGARTERA, PEDRO | D26: Producción | E26: OK | F26: T2 | G26: L2 | H26: ETT | I26: 46055
A27: 23 | B27: SLP | C27: LOBON PERALES, SERGIO | D27: Producción | E27: OK | F27: T2 | G27: L2
A28: 24 | B28: VBY | C28: BINTOV YOCHEV, VESELIN | D28: Producción | E28: OK | F28: T2 | G28: L2
A29: 25 | B29: MGS | C29: GARCIA SILGADO, MARTIN | D29: Producción | E29: OK | F29: T2 | G29: L2 | H29: ETT | I29: 46055
A30: 26 | B30: DAL | C30: ASENSIO LUENGO, DANIEL | D30: Producción | E30: OK | F30: T2 | G30: L2 | H30: ETT | I30: 45965
A31: 27 | B31: PVD | C31: VALLEJO DIAZ, PAULA | D31: Producción | E31: OK | F31: T2 | G31: L2 | H31: ETT | I31: 46146
A32: 28 | B32: JATS | C32: TORREJON SANZ, JUAN ANTONIO | D32: Producción - Electricidad | E32: OK | F32: T2 | G32: L2
A33: 29 | B33: RHG | C33: HERNANDO GONZALEZ, RAUL | D33: Producción - Electricidad | E33: OK | F33: T2 | G33: L2
A34: 30 | B34: RCS | C34: SARDAN, ROBERT CRISTIAN | D34: Producción - Electricidad - L3 | E34: OK | F34: T2 | G34: L2 | H34: ETT | I34: 46132
A35: 31 | B35: SON | C35: OÑATE NUÑEZ, SANTIAGO | D35: Producción - Electricidad | E35: OK | F35: T2 | G35: L2 | H35: PAVONI | I35: 46146
A36: 32 | B36: CCL | C36: CATALINA LOARCE, CESAR | D36: Producción - Electricidad | E36: OK | F36: T2 | G36: L2 | H36: ETT | I36: 46181

Sheet Linea 3
A1: Producción - Electricidad - T1 | B1: ID Operario | C1: Producción - Electricidad T2 | D1: Producción - T1 | E1: Producción - T2 | F1: Total operarios | J1: Categoría | K1: Cantidad
A2: =SUMPRODUCT((D5:D9994="Producción - Electricidad")*(E5:E9994="OK")*(F5:F9994="T1")*(1+ISNUMBER(H5:H9994)*((0.2+0.3*(IFERROR((TODAY()-H5:H9994)/30.44,0)>3)+0.25*(IFERROR((TODAY()-H5:H9994)/30.44,0)>6)+0.25*(IFERROR((TODAY()-H5:H9994)/30.44,0)>9))-1))) -> 6 | C2: =SUMPRODUCT((D5:D9994="Producción - Electricidad")*(E5:E9994="OK")*(F5:F9994="T2")*(1+ISNUMBER(H5:H9994)*((0.2+0.3*(IFERROR((TODAY()-H5:H9994)/30.44,0)>3)+0.25*(IFERROR((TODAY()-H5:H9994)/30.44,0)>6)+0.25*(IFERROR((TODAY()-H5:H9994)/30.44,0)>9))-1))) -> 5 | D2: =SUMPRODUCT((D5:D9994="Producción")*(E5:E9994="OK")*(F5:F9994="T1")*(1+ISNUMBER(H5:H9994)*((0.2+0.3*(IFERROR((TODAY()-H5:H9994)/30.44,0)>3)+0.25*(IFERROR((TODAY()-H5:H9994)/30.44,0)>6)+0.25*(IFERROR((TODAY()-H5:H9994)/30.44,0)>9))-1))) -> 7 | E2: =SUMPRODUCT((D5:D9994="Producción")*(E5:E9994="OK")*(F5:F9994="T2")*(1+ISNUMBER(H5:H9994)*((0.2+0.3*(IFERROR((TODAY()-H5:H9994)/30.44,0)>3)+0.25*(IFERROR((TODAY()-H5:H9994)/30.44,0)>6)+0.25*(IFERROR((TODAY()-H5:H9994)/30.44,0)>9))-1))) -> 7 | F2: =SUM(A2:E2) -> 25 | J2: Elec-T1 | K2: =A2 -> 6
J3: Elec-T2 | K3: =C2 -> 5
A4: Cantidad | B4: ID Operario | C4: Nombre | D4: Departamento | E4: Estado | F4: Turno | G4: Linea | H4: ETT | I4: Fecha | J4: Prod-T1 | K4: =D2 -> 7
A5: 1 | C5: BLANCO, JAVIER | D5: Producción | E5: Jefe | F5: T1 | G5: L3 | J5: Prod-T2 | K5: =E2 -> 7
A6: 2 | B6: JVM | C6: VILLARREAL MATEO, JORGE | D6: Producción/baja | E6: OK | F6: T1 | G6: L3
A7: 3 | B7: CAL | C7: APARICIO LEON, CESAR ANTONIO | D7: Producción | E7: OK | F7: T1 | G7: L3
A8: 4 | B8: DCCA | C8: CERRADA CANALES, DANIEL | D8: Producción | E8: OK | F8: T1 | G8: L3 | H8: ETT | I8: 46125
A9: 5 | B9: ADLR | C9: DE LLAMES RODRÍGUEZ, ANGEL | D9: Producción | E9: OK | F9: T1 | G9: L3 | H9: ETT | I9: 46076
A10: 6 | B10: MJJ | C10: JIMENEZ JURADO, MATEO | D10: Producción | E10: OK | F10: T1 | G10: L3
A11: 7 | B11: RPE | C11: PUEBLA ESPINOSA, RAUL | D11: Producción | E11: OK | F11: T1 | G11: L3
A12: 8 | B12: FJRR | C12: RODRIGUEZ REYES, FRANCISCO JAVIER | D12: Producción | E12: OK | F12: T1 | G12: L3 | H12: ETT | I12: 46076
A13: 9 | B13: ISAC | C13: SANCHEZ CARMENA, IVAN | D13: Producción | E13: OK | F13: T1 | G13: L3
A14: 10 | B14: DBDR | C14: BARROSO DE ROA, DANIEL | D14: Producción - Electricidad | E14: OK | F14: T1 | G14: L3 | H14: Sindicato | I14: Sindicato
A15: 11 | B15: DGC | C15: GALAN CARRASCO, DAVID | D15: Producción - Electricidad | E15: OK | F15: T1 | G15: L3 | H15: PAVONI | I15: 46181
A16: 12 | B16: AHB | C16: HERNANDEZ BARGUEÑO, ALBERTO | D16: Producción - Electricidad | E16: OK | F16: T1 | G16: L3
A17: 13 | B17: CJC | C17: JUANES CARMONA, CHRISTIAN | D17: Producción - Electricidad | E17: OK | F17: T1 | G17: L3
A18: 14 | B18: CRJ | C18: RODRIGUZ JIMENEZ, CRISTIAN | D18: Producción - Electricidad | E18: OK | F18: T1 | G18: L3
A19: 15 | B19: HSC | C19: SAEZ CONDE, HUGO | D19: Producción - Electricidad | E19: OK | F19: T1 | G19: L3 | H19: PAVONI | I19: 46202
A20: 16 | C20: GARCIA CRESPO, JORGE | D20: Producción | E20: Jefe | F20: T2 | G20: L3
A21: 17 | B21: RNC | C21: NUÑEZ CABALLERO, RICARDO | D21: Producción/baja | E21: OK | F21: T2 | G21: L3
A22: 18 | B22: AFCG | C22: CASTAÑO GARCIA, ANDRES FELIPE | D22: Producción | E22: OK | F22: T2 | G22: L3
A23: 19 | B23: JFR | C23: FERNANDEZ RAMIREZ, JORGE | D23: Producción/baja | E23: OK | F23: T2 | G23: L3
A24: 20 | B24: IFF | C24: FERRER FERNANDEZ, IVAN | D24: Producción | E24: OK | F24: T2 | G24: L3
A25: 21 | B25: SLMM | C25: LOPEZ MONTERO MORENO, SONIA | D25: Producción | E25: OK | F25: T2 | G25: L3
A26: 22 | B26: ACR | C26: CORPAS RAMIRO, ALVARO | D26: Producción | E26: OK | F26: T2 | G26: L3
A27: 23 | B27: JJRO | C27: RODRIGUEZ ORDUÑEZ, JESUS JAVIER | D27: Producción | E27: OK | F27: T2 | G27: L3
A28: 24 | B28: ADPL | C28: DE PABLO LEAL, ADRIAN | D28: Producción | E28: OK | F28: T2 | G28: L3 | H28: ETT | I28: 46084
A29: 25 | B29: MJME | C29: MORILLO ERAZO, MARCELO JAVIER | D29: Producción | E29: OK | F29: T2 | G29: L3 | H29: ETT | I29: 46119
A30: 26 | B30: DHLB | C30: HERNANDEZ LOPEZ-BALTASAR, DAVID | D30: Producción - Electricidad | E30: OK | F30: T2 | G30: L3 | H30: ETT | I30: 46069
A31: 27 | B31: ABM | C31: BENAIGUES MENA, ANGEL | D31: Producción - Electricidad | E31: OK | F31: T2 | G31: L3
A32: 28 | B32: FJPP | C32: PASCUAL PLAZA, FRANCISCO JOSE | D32: Producción - Electricidad | E32: OK | F32: T2 | G32: L3
A33: 29 | B33: JJRM | C33: RUIZ MARTINEZ, JUAN JOSE | D33: Producción - Electricidad | E33: OK | F33: T2 | G33: L3
A34: 30 | B34: MDVO | C34: VILLANUEVA OLMEDO, Mª DOLORES | D34: Producción - Electricidad | E34: OK | F34: T2 | G34: L3 | H34: PAVONI | I34: 46146

Sheet Linea 4
A1: Producción - Electricidad - T1 | C1: Producción - Electricidad T2 | D1: Producción - T1 | E1: Producción - T2 | F1: Total operarios | J1: Categoría | K1: Cantidad | M1: 1 | N1: Cubos
A2: =SUMPRODUCT((D5:D9991="Producción - Electricidad")*(E5:E9991="OK")*(F5:F9991="T1")*(1+ISNUMBER(H5:H9991)*((0.2+0.3*(IFERROR((TODAY()-H5:H9991)/30.44,0)>3)+0.25*(IFERROR((TODAY()-H5:H9991)/30.44,0)>6)+0.25*(IFERROR((TODAY()-H5:H9991)/30.44,0)>9))-1))) -> 2 | C2: =SUMPRODUCT((D5:D9991="Producción - Electricidad")*(E5:E9991="OK")*(F5:F9991="T2")*(1+ISNUMBER(H5:H9991)*((0.2+0.3*(IFERROR((TODAY()-H5:H9991)/30.44,0)>3)+0.25*(IFERROR((TODAY()-H5:H9991)/30.44,0)>6)+0.25*(IFERROR((TODAY()-H5:H9991)/30.44,0)>9))-1))) -> 3 | D2: =SUMPRODUCT((D5:D9991="Producción")*(E5:E9991="OK")*(F5:F9991="T1")*(1+ISNUMBER(H5:H9991)*((0.2+0.3*(IFERROR((TODAY()-H5:H9991)/30.44,0)>3)+0.25*(IFERROR((TODAY()-H5:H9991)/30.44,0)>6)+0.25*(IFERROR((TODAY()-H5:H9991)/30.44,0)>9))-1))) -> 4 | E2: =SUMPRODUCT((D5:D9991="Producción")*(E5:E9991="OK")*(F5:F9991="T2")*(1+ISNUMBER(H5:H9991)*((0.2+0.3*(IFERROR((TODAY()-H5:H9991)/30.44,0)>3)+0.25*(IFERROR((TODAY()-H5:H9991)/30.44,0)>6)+0.25*(IFERROR((TODAY()-H5:H9991)/30.44,0)>9))-1))) -> 5 | F2: =SUM(A2:E2) -> 14 | J2: Elec-T1 | K2: =A2 -> 2 | M2: 1 | N2: 0
J3: Elec-T2 | K3: =C2 -> 3
A4: Cantidad | B4: ID Operario | C4: Nombre | D4: Departamento | E4: Estado | F4: Turno | G4: Linea | H4: ETT | I4: Fecha | J4: Prod-T1 | K4: =D2 -> 4
A5: 1 | C5: SANTURDE, DAVID | D5: Producción - Electricidad | E5: Jefe | F5: T1 | G5: L4 | J5: Prod-T2 | K5: =E2 -> 5
A6: 2 | B6: SMGA | C6: MATEO GARCIA, SANDRA | D6: Producción | E6: OK | F6: T1 | G6: L4
A7: 3 | B7: TO | C7: OUHABI, TARIK | D7: Producción | E7: OK | F7: T1 | G7: L4
A8: 4 | B8: NQG | C8: QUINTANA GONZALEZ, NAIARA | D8: Producción | E8: OK | F8: T1 | G8: L4 | H8: ETT | I8: 46084
A9: 5 | B9: ISCO | C9: SILVIU CONSTANTIN, IOSIF - NO SE RENUEVA | D9: Producción | E9: OK | F9: T1 | G9: L4 | H9: ETT | I9: 46161
A10: 6 | C10: NICULA, STEFAN | D10: Producción - BAJA | E10: OK | F10: T1 | G10: L4 | H10: ETT | I10: 46188
A11: 7 | B11: ACJ | C11: CINTADO JIMENEZ, AGUEDA | D11: Producción - Electricidad | E11: OK | F11: T1 | G11: L4
A12: 8 | B12: AHG | C12: HERRANDO GARCIA, ALBERTO | D12: Producción - Electricidad | E12: OK | F12: T1 | G12: L4
A13: 9 | B13: DTF | C13: TAPIAS FRANCO, DANIELA | D13: Producción - Electricidad | E13: OK | F13: T1 | G13: L4 | H13: D | I13: 46146
A14: 10 | B14: LAC | C14: AGUADO CABALLERO, LUCIA | D14: Producción - Electricidad | E14: OK | F14: T1 | G14: L4 | H14: ETT | I14: 46167
A15: 11 | B15: FJLP | C15: LEON PADILLO, FRANCISCO JAVIER | D15: Producción - Electricidad - BAJA | E15: Baja | F15: T1 | G15: L4
A16: 12 | B16: JLP | C16: UREÑA PORTERO, JAVIER Paternidad | D16: Producción/Baja | E16: Baja | F16: T1 | G16: L4
A17: 13 | C17: HERNANDEZ, LUIS MIGUEL | D17: Producción | E17: Jefe | F17: T2 | G17: L4
A18: 14 | B18: AMGA | C18: MARTIN GARCIA, ALEJANDRO | D18: Producción | E18: OK | F18: T2 | G18: L4
A19: 15 | B19: RRB | C19: RODRIGUEZ BERLINCHES, REGINO | D19: Producción | E19: OK | F19: T2 | G19: L4 | H19: ETT | I19: 46132
A20: 16 | B20: PJNM | C20: NUNES MARIA, PAULO JORGE Vacaciones | D20: Producción | E20: OK | F20: T2 | G20: L4
A21: 17 | B21: VRG | C21: ROMERO GONZALEZ, VICTOR | D21: Producción | E21: OK | F21: T2 | G21: L4
A22: 18 | B22: AAOV | C22: APARICIO ORTEGA VILLAIZAN, ALEJANDRO | D22: Producción | E22: OK | F22: T2 | G22: L4 | H22: ETT | I22: 46174
A23: 19 | B23: AAB | C23: ARENAS BUIZA, ANGEL | D23: Producción - Electricidad | E23: OK | F23: T2 | G23: L4
A24: 21 | B24: MOH | C24: OCHKIF EL HELALI, MOHAMED | D24: Producción - Electricidad | E24: OK | F24: T2 | G24: L4 | H24: ETT | I24: 46181
A25: 22 | B25: ALGN | C25: GARCIA NEVES, ALEJANDRA (Panelado) | D25: Producción/Panelado | E25: OK | F25: T2 | G25: L4
A26: 23 | B26: FSGR | C26: GONZALEZ RIOS, FRANK STIBEN | D26: Producción/Baja | E26: Baja | F26: T1 | G26: L4 | H26: ETT | I26: 46203
A27: 24 | B27: IFE | C27: IVAN FERNANDEZ ESPINOSA | D27: Producción - Electricidad | E27: OK | F27: T2 | G27: L4 | H27: ETT | I27: 46153

Sheet Linea 5
A1: Producción - Electricidad - T1 | B1: ID Operario | C1: Producción - Electricidad T2 | D1: Producción - T1 | E1: Producción - T2 | F1: Total operarios | J1: Categoría | K1: Cantidad
A2: =SUMPRODUCT((D5:D194="Producción - Electricidad")*(E5:E194="OK")*(F5:F194="T1")*(1+ISNUMBER(H5:H194)*((0.2+0.3*(IFERROR((TODAY()-H5:H194)/30.44,0)>3)+0.25*(IFERROR((TODAY()-H5:H194)/30.44,0)>6)+0.25*(IFERROR((TODAY()-H5:H194)/30.44,0)>9))-1))) -> 5 | C2: =SUMPRODUCT((D5:D194="Producción - Electricidad")*(E5:E194="OK")*(F5:F194="T2")*(1+ISNUMBER(H5:H194)*((0.2+0.3*(IFERROR((TODAY()-H5:H194)/30.44,0)>3)+0.25*(IFERROR((TODAY()-H5:H194)/30.44,0)>6)+0.25*(IFERROR((TODAY()-H5:H194)/30.44,0)>9))-1))) -> 3 | D2: =SUMPRODUCT((D5:D194="Producción")*(E5:E194="OK")*(F5:F194="T1")*(1+ISNUMBER(H5:H194)*((0.2+0.3*(IFERROR((TODAY()-H5:H194)/30.44,0)>3)+0.25*(IFERROR((TODAY()-H5:H194)/30.44,0)>6)+0.25*(IFERROR((TODAY()-H5:H194)/30.44,0)>9))-1))) -> 8 | E2: =SUMPRODUCT((D5:D194="Producción")*(E5:E194="OK")*(F5:F194="T2")*(1+ISNUMBER(H5:H194)*((0.2+0.3*(IFERROR((TODAY()-H5:H194)/30.44,0)>3)+0.25*(IFERROR((TODAY()-H5:H194)/30.44,0)>6)+0.25*(IFERROR((TODAY()-H5:H194)/30.44,0)>9))-1))) -> 6 | F2: =SUM(A2:E2) -> 22 | J2: Elec-T1 | K2: =A2 -> 5
J3: Elec-T2 | K3: =C2 -> 3
A4: Cantidad | B4: ID Operario | C4: Nombre | D4: Departamento | E4: Estado | F4: Turno | G4: Linea | H4: ETT | I4: Fecha | J4: Prod-T1 | K4: =D2 -> 8
A5: 1 | C5: ROMERO , ANTONIO ALFREDO | D5: Producción | E5: Jefe | F5: T1 | G5: L5 | J5: Prod-T2 | K5: =E2 -> 6
A6: 2 | B6: FMDLSM | C6: DELOS SANTOS MARQUEZ, FRANCISCO M. | D6: Producción | E6: OK | F6: T1 | G6: L5
A7: 3 | B7: IBM | C7: BLANCO MARTIN, ISMAEL | D7: Producción | E7: OK | F7: T1 | G7: L5
A8: 4 | B8: JJBC | C8: BENTACOURT CARDONA, JOSE JAIME | D8: Producción | E8: OK | F8: T1 | G8: L5
A9: 5 | B9: NACR | C9: CASTELLANOS RODRIGUEZ, NELSON ANDRES | D9: Producción | E9: OK | F9: T1 | G9: L5 | H9: ETT | I9: 46062
A10: 6 | B10: ADCE | C10: DORADO DEL CERRO, AISHA | D10: Producción | E10: OK | F10: T1 | G10: L5 | H10: ETT | I10: 46084
A11: 7 | B11: JSBC | C11: BETANCUR CASTRO, JHON STIVEN | D11: Producción | E11: OK | F11: T1 | G11: L5 | H11: ETT | I11: 46062
A12: 8 | B12: MBO | C12: BOUHAZAMA, MOHAMED Pasa a L2 semana S25 - Idioma - ¿Tecnico? | D12: Producción | E12: OK | F12: T1 | G12: L5 | H12: ETT | I12: 46181
A13: 10 | B13: NCM | C13: CAMPOS MARTÍN, NAYARA | D13: Producción | E13: OK | F13: T1 | G13: L5 | H13: ETT | I13: 46188
A14: 11 | B14: RARL | C14: ARAGONES LOPEZ, RICARDO | D14: Producción - Electricidad | E14: OK | F14: T1 | G14: L5
A15: 12 | B15: KAGG | C15: GORDILLO GUERRERO, KEVIN ALEXANDER | D15: Producción - Electricidad | E15: OK | F15: T1 | G15: L5
A16: 13 | B16: JLSM | C16: SANCHEZ MURILLO, JOSE LUIS | D16: Producción - Electricidad | E16: OK | F16: T1 | G16: L5
A17: 14 | B17: DMO | C17: MANZANERO OCAÑA, DAVID | D17: Producción - Electricidad | E17: OK | F17: T1 | G17: L5 | H17: PAVONI | I17: 46146
A18: 15 | B18: FJRG | C18: RUIZ GARCIA , FRANCISCO JAVIER | D18: Producción - Electricidad | E18: OK | F18: T1 | G18: L5
A19: 16 | C19: JARA VERA, OSCAR ANDRES | D19: Producción | E19: Jefe | F19: T2 | G19: L5
A20: 17 | B20: EMJ | C20: MARTIN JIMENEZ, ESTEBAN | D20: Producción | E20: OK | F20: T2 | G20: L5
A21: 18 | B21: PPSC | C21: SANCHEZ CENAMOR, PEDRO PABLO | D21: Producción | E21: OK | F21: T2 | G21: L5
A22: 19 | B22: DSM | C22: SANZ MELERO, DANIEL | D22: Producción | E22: OK | F22: T2 | G22: L5 | H22: ETT | I22: 45979
A23: 20 | B23: SMJ | C23: MARTINEZ JAIME, SEBASTIAN | D23: Producción | E23: OK | F23: T2 | G23: L5 | H23: ETT | I23: 46090
A24: 21 | B24: JAPP | C24: PUEBLA PINILLOS, JUAN ANTONIO | D24: Producción | E24: OK | F24: T2 | G24: L5 | H24: ETT | I24: 46090
A25: 22 | B25: JAM | C25: APARICIO MIJARRA, JULIAN | D25: Producción | E25: OK | F25: T2 | G25: L5 | H25: ETT | I25: 46119
A26: 23 | B26: CMOM | C26: MOYANO MORCILLO, CHRISTIAN | D26: Producción - Electricidad | E26: OK | F26: T2 | G26: L5
A27: 24 | B27: JMPS | C27: SANCHEZ PANIAGUA, JOSE MARIA Vacaciones | D27: Producción - Electricidad | E27: OK | F27: T2 | G27: L5
A28: 25 | B28: OHFD | C28: FRANCO DELGADO, OMAR HERNANDO | D28: Producción - Electricidad | E28: OK | F28: T2 | G28: L5 | H28: PAVONI | I28: 46153
A29: 27 | B29: CGG | C29: GARCIA GUERRA, CARLOS (Paternidad) | D29: Producción/baja | E29: OK | F29: T2 | G29: L5
A30: 28 | B30: MVN | C30: VILLA NICOLAS, MARIANO | D30: Producción/baja | E30: OK | F30: T2 | G30: L5

Sheet BOX
A1: Producción - Electricidad - T1 | B1: ID Operario | C1: Producción - Electricidad T2 | D1: Producción - T1 | E1: Producción - T2 | F1: Total operarios | J1: Categoría | K1: Cantidad
A2: {=SUMPRODUCT((D5:D199="BOX-ELEC")*(E5:E199="OK")*(F5:F199="T1")*(1+ISNUMBER(H5:H199)*((0.2+0.3*(IFERROR((TODAY()-_xlfn.SINGLE(H5:H199))/30.44,0)>3)+0.25*(IFERROR((TODAY()-_xlfn.SINGLE(H5:H199))/30.44,0)>6)+0.25*(IFERROR((TODAY()-_xlfn.SINGLE(H5:H199))/30.44,0)>9))-1)))} -> 0 | C2: {=SUMPRODUCT((D5:D199="BOX-ELEC")*(E5:E199="OK")*(F5:F199="T2")*(1+ISNUMBER(H5:H199)*((0.2+0.3*(IFERROR((TODAY()-_xlfn.SINGLE(H5:H199))/30.44,0)>3)+0.25*(IFERROR((TODAY()-_xlfn.SINGLE(H5:H199))/30.44,0)>6)+0.25*(IFERROR((TODAY()-_xlfn.SINGLE(H5:H199))/30.44,0)>9))-1)))} -> 2 | D2: {=SUMPRODUCT((D5:D199="BOX")*(E5:E199="OK")*(F5:F199="T1")*(1+ISNUMBER(H5:H199)*((0.2+0.3*(IFERROR((TODAY()-_xlfn.SINGLE(H5:H199))/30.44,0)>3)+0.25*(IFERROR((TODAY()-_xlfn.SINGLE(H5:H199))/30.44,0)>6)+0.25*(IFERROR((TODAY()-_xlfn.SINGLE(H5:H199))/30.44,0)>9))-1)))} -> 0 | E2: {=SUMPRODUCT((D5:D199="BOX")*(E5:E199="OK")*(F5:F199="T2")*(1+ISNUMBER(H5:H199)*((0.2+0.3*(IFERROR((TODAY()-_xlfn.SINGLE(H5:H199))/30.44,0)>3)+0.25*(IFERROR((TODAY()-_xlfn.SINGLE(H5:H199))/30.44,0)>6)+0.25*(IFERROR((TODAY()-_xlfn.SINGLE(H5:H199))/30.44,0)>9))-1)))} -> 1 | F2: =SUM(A2:E2) -> 3 | J2: Elec-T1 | K2: =A2 -> 0
J3: Elec-T2 | K3: =C2 -> 2
A4: Cantidad | B4: ID Operario | C4: Nombre | D4: Departamento | E4: Estado | F4: Turno | G4: Linea | H4: ETT | I4: Fecha | J4: Prod-T1 | K4: =D2 -> 0
B5: MMP | C5: MONROY PRIETO, MARCOS | D5: BOX-ELEC | E5: OK | F5: Baja | G5: BOX1 | J5: Prod-T2 | K5: =E2 -> 1
A6: 1 | B6: LMA | C6: MORENO ARENAS, LUIS | D6: BOX-ELEC | E6: OK | F6: T2 | G6: BOX1
A7: 2 | B7: LBH | C7: BELLON HERNANDEZ, LUIS | D7: BOX | E7: OK | F7: T2 | G7: BOX1
A8: 3 | B8: AST | C8: SÁNCHEZ TORREJÓN, AARÓN L5 | D8: BOX-ELEC | E8: OK | F8: T2 | G8: BOX1 | I8: 46125
A35: Cantidad | B35: ID Operario | C35: Nombre | D35: Departamento | E35: Estado | F35: Turno | G35: Linea | H35: ETT
C36: MONROY PRIETO, MARCOS | D36: Producción | E36: BAJA | F36: Baja | G36: BOX1
A37: 1 | B37: LMA | C37: MORENO ARENAS, LUIS | D37: Producción | E37: OK | F37: T2 | G37: BOX1
A38: 2 | B38: LBH | C38: BELLON HERNANDEZ, LUIS | D38: Producción | E38: OK | F38: T2 | G38: BOX1
A39: 3 | B39: AST | C39: SÁNCHEZ TORREJÓN, AARÓN | D39: Producción | E39: OK | F39: T2 | G39: BOX1 | H39: 46125

Sheet Cuadros
A1: Cuadros - Electricidad - T1 | B1: ID Operario | C1: Cuadors - Electricidad T2 | D1: Cuadros-Electricidad - T3 | F1: Total operarios | J1: Categoría | K1: Cantidad
A2: {=SUMPRODUCT((D5:D199="Cuadros")*(E5:E199="OK")*(F5:F199="T1")*(1+ISNUMBER(H5:H199)*((0.2+0.3*(IFERROR((TODAY()-_xlfn.SINGLE(H5:H199))/30.44,0)>3)+0.25*(IFERROR((TODAY()-_xlfn.SINGLE(H5:H199))/30.44,0)>6)+0.25*(IFERROR((TODAY()-_xlfn.SINGLE(H5:H199))/30.44,0)>9))-1)))} -> 8 | C2: {=SUMPRODUCT((D5:D199="Cuadros")*(E5:E199="OK")*(F5:F199="T2")*(1+ISNUMBER(H5:H199)*((0.2+0.3*(IFERROR((TODAY()-_xlfn.SINGLE(H5:H199))/30.44,0)>3)+0.25*(IFERROR((TODAY()-_xlfn.SINGLE(H5:H199))/30.44,0)>6)+0.25*(IFERROR((TODAY()-_xlfn.SINGLE(H5:H199))/30.44,0)>9))-1)))} -> 7 | D2: {=SUMPRODUCT((D5:D199="Cuadros")*(E5:E199="OK")*(F5:F199="T3")*(1+ISNUMBER(H5:H199)*((0.2+0.3*(IFERROR((TODAY()-_xlfn.SINGLE(H5:H199))/30.44,0)>3)+0.25*(IFERROR((TODAY()-_xlfn.SINGLE(H5:H199))/30.44,0)>6)+0.25*(IFERROR((TODAY()-_xlfn.SINGLE(H5:H199))/30.44,0)>9))-1)))} -> 0 | E2: =SUMPRODUCT((D5:D199="Producción")*(E5:E199="OK")*(F5:F199="T2")*(1+ISNUMBER(H5:H199)*((0.2+0.3*(IFERROR((TODAY()-H5:H199)/30.44,0)>3)+0.25*(IFERROR((TODAY()-H5:H199)/30.44,0)>6)+0.25*(IFERROR((TODAY()-H5:H199)/30.44,0)>9))-1))) -> 0 | F2: =SUM(A2:E2) -> 15 | J2: Cuadros-T1 | K2: =A2 -> 8
J3: Cuadros-T2 | K3: =C2 -> 7
A4: Cantidad | B4: ID Operario | C4: Nombre | D4: Departamento | E4: Estado | F4: Turno | G4: Linea | H4: ETT | I4: Fecha | J4: Cuadros-T3 | K4: =D2 -> 0
A5: 1 | B5: JMRT | C5: RODRÍGUEZ TALAVERA, JUAN MANUEL | D5: Cuadros | E5: OK | F5: T1 | K5: =E2 -> 0
A6: á | B6: LECR | C6: CASAS RAMÍREZ, LUIS ENRIQUE | D6: Cuadros | E6: OK | F6: T1
A7: 3 | B7: JLVH | C7: VEGA HERNÁNDEZ, JOSE LUIS | D7: Cuadros | E7: OK | F7: T1
A8: 4 | B8: MDSP | C8: DE SOUSA PEREIRA, MARIA ISABEL | D8: Cuadros | E8: OK | F8: T1
A9: 5 | B9: AAA | C9: AYALA ARROYO,ALBA | D9: Cuadros | E9: OK | F9: T1
A10: 6 | B10: LTG | C10: TRIVIÑO GUERRERO, LUCÍA | D10: Cuadros | E10: OK | F10: T1 | H10: PAVONI
A11: 7 | B11: ACVA | C11: VALLDIVIESO ANTON, ANA CELIA | D11: Cuadros | E11: OK | F11: T1 | H11: PAVONI
A12: 8 | B12: FJSM | C12: SELLES DE MANUEL, FRANCISCO JAVIER | D12: Cuadros | E12: OK | F12: T1 | I12: 8
A13: 9 | B13: JRE | C13: ROMERO ENAMORADO, JORGE | D13: Cuadros | E13: OK | F13: T2
A14: 10 | B14: ALPL | C14: PALOMO LOPEZ, ALFREDO | D14: Cuadros | E14: OK | F14: T2
A15: 11 | B15: LSN | C15: SARTI NAVARRO, LIDIA | D15: Cuadros | E15: OK | F15: T2
A16: 12 | B16: ISB | C16: SOLERA RISCO, IARA | D16: Cuadros | E16: OK | F16: T2 | H16: PAVONI
A17: 13 | B17: JLMR | C17: MORENO RISCO, JUAN LUIS | D17: Cuadros | E17: OK | F17: T2 | H17: SI | I17: 45986
A18: 14 | B18: JFEA | C18: ESTRADA ACEVEDO, JHON FERNANDO | D18: Cuadros | E18: OK | F18: T2 | H18: SI | I18: 46174
A19: 15 | C19: KASMI, FAYSAL No se incorpora aun | D19: Cuadros | E19: OK | F19: T2 | H19: SI | I19: 46174

Sheet Jefes 
B2: Nombre | C2: Departamento
B3: Carmelo Valero Perez | C3: Producción - Electricidad | AJ3: S | AK3: S
B4: Federico Martin Cid | C4: Producción - Electricidad | AB4: S | AM4: S
B5: Gregorio Martinez | C5: Producción - Mecanizado | AK5: S | AL5: 1 | AM5: S
B6: Luís Lama | C6: Producción
B7: Pedro Corchado | C7: Producción | AJ7: S | AK7: S
B8: Pedro Escudero | C8: Producción - Test Final
B9: Raul Bowen Oliver | C9: Producción | AE9: S | AF9: S
B10: Sonia García | C10: Producción - Baterías | AJ10: S | AK10: S
B11: Olga | C11: Produccion - Planificacion
B17: Westley Chamorro Garcia | C17: Producción - Electricidad | D17: =IF(COUNTBLANK((E17:BI17))=54,"Check",IF(COUNTBLANK(E17:BI17)=57,"Falta pedir","Ok")) -> Ok | M17: S | AM17: S
